<?xml version="1.0" ?>
<!-- =================================================================================== -->
<!-- |    This document was autogenerated by xacro from fw-max.xacro                   | -->
<!-- |    EDITING THIS FILE BY HAND IS NOT RECOMMENDED                                 | -->
<!-- =================================================================================== -->
<robot name="fw_max">
  <link name="base_footprint">
    </link>
  <link name="base_link">
    <visual>
      <origin xyz="0 0 0.1" rpy="0 0 0"/>  <!-- Adjust height as needed -->
      <geometry>
        <box size="0.6 0.4 0.15"/>         <!-- Length, Width, Height in meters -->
      </geometry>
      <material name="Gray">
        <color rgba="0.5 0.5 0.5 1.0"/>
      </material>
    </visual>
    <inertial>
      <origin xyz="0 0 0"/>
      <mass value="75"/>
      <inertia ixx="2.8658" ixy="0" ixz="0" iyy="6.7327" iyz="0" izz="7.6506"/>
    </inertial>
  </link>
  <joint name="base_link2base_footprint" type="fixed">
    <parent link="base_footprint"/>
    <child link="base_link"/>
    <origin xyz="0 0 0.032"/>
  </joint>
  <link name="left_steering_hinge">
    <visual>
      <geometry>
        <cylinder length="0.005" radius="0.02"/>
      </geometry>
      <origin rpy="1.57 0 0" xyz="0 0 0"/>
      <material name="black">
        <color rgba="0.0 0.0 0.0 1.0"/>
      </material>
    </visual>
    <collision>
      <geometry>
        <cylinder length="0.005" radius="0.01"/>
      </geometry>
      <origin rpy="1.57 0.0 0.0" xyz="0.0 0.0 0.0"/>
    </collision>
    <inertial>
      <origin xyz="0 0 0"/>
      <mass value="1"/>
      <inertia ixx="2.7E-05" ixy="0" ixz="0" iyy="2.7E-05" iyz="0" izz="5E-05"/>
    </inertial>
  </link>
  <joint name="left_steering_hinge_joint" type="revolute">
    <parent link="base_link"/>
    <child link="left_steering_hinge"/>
    <origin xyz="0.3 0.225 0"/>
    <axis xyz="0 0 1"/>
    <limit effort="50.0" lower="-3.14" upper="3.14" velocity="50.0"/>
  </joint>
  <transmission name="left_steering_hinge_trans">
    <type>transmission_interface/SimpleTransmission</type>
    <joint name="left_steering_hinge_joint">
      <hardwareInterface>position</hardwareInterface>
    </joint>
    <actuator name="left_steering_hinge_motor">
      <mechanicalReduction>1</mechanicalReduction>
    </actuator>
  </transmission>
  <link name="left_front_wheel">
    <visual>
      <geometry>
        <mesh filename="file:///home/azif/projetcs/fw-max-ackerman/install/ackerman_description/share/ackerman_description/meshes/fw-max-luntai.STL" scale="1 1 1"/>
      </geometry>
      <origin rpy="0 3.14 1.57" xyz="0.135 0.055 0.135"/>
      <material name="black">
        <color rgba="0.0 0.0 0.0 1.0"/>
      </material>
    </visual>
    <collision>
      <geometry>
        <cylinder length="0.08" radius="0.125"/>
      </geometry>
      <origin rpy="1.57 0.0 0.0" xyz="0.0 0.0 0.0"/>
    </collision>
    <inertial>
      <origin xyz="0 0 0"/>
      <mass value="1.0"/>
      <inertia ixx="0.006040" ixy="0" ixz="0" iyy="0.006040" iyz="0" izz="0.007812"/>
    </inertial>
  </link>
  <joint name="left_front_wheel_joint" type="continuous">
    <parent link="left_steering_hinge"/>
    <child link="left_front_wheel"/>
    <origin xyz="0 0 0"/>
    <axis xyz="0 1 0"/>
    <limit effort="10" velocity="1000"/>
  </joint>
  <transmission name="left_front_wheel_trans">
    <type>transmission_interface/SimpleTransmission</type>
    <joint name="left_front_wheel_joint">
      <hardwareInterface>velocity</hardwareInterface>
    </joint>
    <actuator name="left_front_wheel_motor">
      <mechanicalReduction>1</mechanicalReduction>
    </actuator>
  </transmission>
  <link name="right_steering_hinge">
    <visual>
      <geometry>
        <cylinder length="0.005" radius="0.02"/>
      </geometry>
      <origin rpy="1.57 0 0" xyz="0 0 0"/>
      <material name="black">
        <color rgba="0.0 0.0 0.0 1.0"/>
      </material>
    </visual>
    <collision>
      <geometry>
        <cylinder length="0.005" radius="0.01"/>
      </geometry>
      <origin rpy="1.57 0.0 0.0" xyz="0.0 0.0 0.0"/>
    </collision>
    <inertial>
      <origin xyz="0 0 0"/>
      <mass value="1"/>
      <inertia ixx="2.7E-05" ixy="0" ixz="0" iyy="2.7E-05" iyz="0" izz="5E-05"/>
    </inertial>
  </link>
  <joint name="right_steering_hinge_joint" type="revolute">
    <parent link="base_link"/>
    <child link="right_steering_hinge"/>
    <origin xyz="0.3 -0.225 0"/>
    <axis xyz="0 0 1"/>
    <limit effort="50.0" lower="-3.14" upper="3.14" velocity="50.0"/>
    <mimic joint="left_steering_hinge_joint" multiplier="1.0" offset="0.0"/>
  </joint>
  <transmission name="right_steering_hinge_trans">
    <type>transmission_interface/SimpleTransmission</type>
    <joint name="right_steering_hinge_joint">
      <hardwareInterface>position</hardwareInterface>
    </joint>
    <actuator name="right_steering_hinge_motor">
      <mechanicalReduction>1</mechanicalReduction>
    </actuator>
  </transmission>
  <link name="right_front_wheel">
    <visual>
      <geometry>
        <mesh filename="file:///home/azif/projetcs/fw-max-ackerman/install/ackerman_description/share/ackerman_description/meshes/fw-max-luntai.STL" scale="1 1 1"/>
      </geometry>
      <origin rpy="0 0 1.57" xyz="0.135 -0.055 -0.135"/>
      <material name="black">
        <color rgba="0.0 0.0 0.0 1.0"/>
      </material>
    </visual>
    <collision>
      <geometry>
        <cylinder length="0.08" radius="0.125"/>
      </geometry>
      <origin rpy="1.57 0.0 0.0" xyz="0.0 0.0 0.0"/>
    </collision>
    <inertial>
      <origin xyz="0 0 0"/>
      <mass value="1.0"/>
      <inertia ixx="0.006040" ixy="0" ixz="0" iyy="0.006040" iyz="0" izz="0.007812"/>
    </inertial>
  </link>
  <joint name="right_front_wheel_joint" type="continuous">
    <parent link="right_steering_hinge"/>
    <child link="right_front_wheel"/>
    <origin xyz="0 0 0"/>
    <axis xyz="0 1 0"/>
    <limit effort="10" velocity="1000"/>
  </joint>
  <transmission name="right_front_wheel_trans">
    <type>transmission_interface/SimpleTransmission</type>
    <joint name="right_front_wheel_joint">
      <hardwareInterface>velocity</hardwareInterface>
    </joint>
    <actuator name="right_front_wheel_motor">
      <mechanicalReduction>1</mechanicalReduction>
    </actuator>
  </transmission>
  <link name="rear_left_steering_hinge">
    <visual>
      <geometry>
        <cylinder length="0.005" radius="0.02"/>
      </geometry>
      <origin rpy="1.57 0 0" xyz="0 0 0"/>
      <material name="black">
        <color rgba="0.0 0.0 0.0 1.0"/>
      </material>
    </visual>
    <collision>
      <geometry>
        <cylinder length="0.005" radius="0.01"/>
      </geometry>
      <origin rpy="1.57 0.0 0.0" xyz="0.0 0.0 0.0"/>
    </collision>
    <inertial>
      <origin xyz="0 0 0"/>
      <mass value="1"/>
      <inertia ixx="2.7E-05" ixy="0" ixz="0" iyy="2.7E-05" iyz="0" izz="5E-05"/>
    </inertial>
  </link>
  <joint name="rear_left_steering_hinge_joint" type="revolute">
    <parent link="base_link"/>
    <child link="rear_left_steering_hinge"/>
    <origin xyz="-0.3 0.225 0"/>
    <axis xyz="0 0 1"/>
    <limit effort="50.0" lower="-3.14" upper="3.14" velocity="50.0"/>
    <mimic joint="left_steering_hinge_joint" multiplier="-1.0" offset="0.0"/>
  </joint>
  <transmission name="rear_left_steering_hinge_trans">
    <type>transmission_interface/SimpleTransmission</type>
    <joint name="rear_left_steering_hinge_joint">
      <hardwareInterface>position</hardwareInterface>
    </joint>
    <actuator name="rear_left_steering_hinge_motor">
      <mechanicalReduction>1</mechanicalReduction>
    </actuator>
  </transmission>
  <link name="left_rear_wheel">
    <visual>
      <geometry>
        <mesh filename="file:///home/azif/projetcs/fw-max-ackerman/install/ackerman_description/share/ackerman_description/meshes/fw-max-luntai.STL" scale="1 1 1"/>
      </geometry>
      <origin rpy="0 3.14 1.57" xyz="0.135 0.055 0.135"/>
      <material name="black">
        <color rgba="0.0 0.0 0.0 1.0"/>
      </material>
    </visual>
    <collision>
      <geometry>
        <cylinder length="0.08" radius="0.125"/>
      </geometry>
      <origin rpy="1.57 0.0 0.0" xyz="0.0 0.0 0.0"/>
    </collision>
    <inertial>
      <origin xyz="0 0 0"/>
      <mass value="1.0"/>
      <inertia ixx="0.006040" ixy="0" ixz="0" iyy="0.006040" iyz="0" izz="0.007812"/>
    </inertial>
  </link>
  <joint name="left_rear_wheel_joint" type="continuous">
    <parent link="rear_left_steering_hinge"/>
    <child link="left_rear_wheel"/>
    <origin xyz="0 0.0 0"/>
    <axis xyz="0 1 0"/>
    <limit effort="10" velocity="1000"/>
  </joint>
  <transmission name="left_rear_wheel_trans">
    <type>transmission_interface/SimpleTransmission</type>
    <joint name="left_rear_wheel_joint">
      <hardwareInterface>velocity</hardwareInterface>
    </joint>
    <actuator name="left_rear_wheel_motor">
      <mechanicalReduction>1</mechanicalReduction>
    </actuator>
  </transmission>
  <link name="rear_right_steering_hinge">
    <visual>
      <geometry>
        <cylinder length="0.005" radius="0.02"/>
      </geometry>
      <origin rpy="1.57 0 0" xyz="0 0 0"/>
      <material name="black">
        <color rgba="0.0 0.0 0.0 1.0"/>
      </material>
    </visual>
    <collision>
      <geometry>
        <cylinder length="0.005" radius="0.01"/>
      </geometry>
      <origin rpy="1.57 0.0 0.0" xyz="0.0 0.0 0.0"/>
    </collision>
    <inertial>
      <origin xyz="0 0 0"/>
      <mass value="1"/>
      <inertia ixx="2.7E-05" ixy="0" ixz="0" iyy="2.7E-05" iyz="0" izz="5E-05"/>
    </inertial>
  </link>
  <joint name="rear_right_steering_hinge_joint" type="revolute">
    <parent link="base_link"/>
    <child link="rear_right_steering_hinge"/>
    <origin xyz="-0.3 -0.225 0"/>
    <axis xyz="0 0 1"/>
    <limit effort="50.0" lower="-3.14" upper="3.14" velocity="50.0"/>
    <mimic joint="left_steering_hinge_joint" multiplier="-1.0" offset="0.0"/>
  </joint>
  <transmission name="rear_right_steering_hinge_trans">
    <type>transmission_interface/SimpleTransmission</type>
    <joint name="rear_right_steering_hinge_joint">
      <hardwareInterface>position</hardwareInterface>
    </joint>
    <actuator name="rear_right_steering_hinge_motor">
      <mechanicalReduction>1</mechanicalReduction>
    </actuator>
  </transmission>
  <link name="right_rear_wheel">
    <visual>
      <geometry>
        <mesh filename="file:///home/azif/projetcs/fw-max-ackerman/install/ackerman_description/share/ackerman_description/meshes/fw-max-luntai.STL" scale="1 1 1"/>
      </geometry>
      <origin rpy="0 0 1.57" xyz="0.135 -0.055 -0.135"/>
      <material name="black">
        <color rgba="0.0 0.0 0.0 1.0"/>
      </material>
    </visual>
    <collision>
      <geometry>
        <cylinder length="0.08" radius="0.125"/>
      </geometry>
      <origin rpy="1.57 0.0 0.0" xyz="0.0 0.0 0.0"/>
    </collision>
    <inertial>
      <origin xyz="0 0 0"/>
      <mass value="1.0"/>
      <inertia ixx="0.006040" ixy="0" ixz="0" iyy="0.006040" iyz="0" izz="0.007812"/>
    </inertial>
  </link>
  <joint name="right_rear_wheel_joint" type="continuous">
    <parent link="rear_right_steering_hinge"/>
    <child link="right_rear_wheel"/>
    <origin xyz="0 0.0 0"/>
    <axis xyz="0 1 0"/>
    <limit effort="10" velocity="1000"/>
  </joint>
  <transmission name="right_rear_wheel_trans">
    <type>transmission_interface/SimpleTransmission</type>
    <joint name="right_rear_wheel_joint">
      <hardwareInterface>velocity</hardwareInterface>
    </joint>
    <actuator name="right_rear_wheel_motor">
      <mechanicalReduction>1</mechanicalReduction>
    </actuator>
  </transmission>
  <transmission name="left_rear_wheel_joint_transmission">
    <type>transmission_interface/SimpleTransmission</type>
    <joint name="left_rear_wheel_joint">
      <hardwareInterface>velocity</hardwareInterface>
    </joint>
    <actuator name="left_rear_wheel_joint_actuator">
      <hardwareInterface>velocity</hardwareInterface>
      <mechanicalReduction>1</mechanicalReduction>
    </actuator>
  </transmission>
  <transmission name="right_rear_wheel_joint_transmission">
    <type>transmission_interface/SimpleTransmission</type>
    <joint name="right_rear_wheel_joint">
      <hardwareInterface>velocity</hardwareInterface>
    </joint>
    <actuator name="right_rear_wheel_joint_actuator">
      <hardwareInterface>velocity</hardwareInterface>
      <mechanicalReduction>1</mechanicalReduction>
    </actuator>
  </transmission>
  <transmission name="left_front_wheel_joint_transmission">
    <type>transmission_interface/SimpleTransmission</type>
    <joint name="left_front_wheel_joint">
      <hardwareInterface>velocity</hardwareInterface>
    </joint>
    <actuator name="left_front_wheel_joint_actuator">
      <hardwareInterface>velocity</hardwareInterface>
      <mechanicalReduction>1</mechanicalReduction>
    </actuator>
  </transmission>
  <transmission name="right_front_wheel_joint_transmission">
    <type>transmission_interface/SimpleTransmission</type>
    <joint name="right_front_wheel_joint">
      <hardwareInterface>velocity</hardwareInterface>
    </joint>
    <actuator name="right_front_wheel_joint_actuator">
      <hardwareInterface>velocity</hardwareInterface>
      <mechanicalReduction>1</mechanicalReduction>
    </actuator>
  </transmission>
  <transmission name="left_steering_hinge_joint_transmission">
    <type>transmission_interface/SimpleTransmission</type>
    <joint name="left_steering_hinge_joint">
      <hardwareInterface>position</hardwareInterface>
    </joint>
    <actuator name="left_steering_hinge_joint_actuator">
      <hardwareInterface>position</hardwareInterface>
      <mechanicalReduction>1</mechanicalReduction>
    </actuator>
  </transmission>
  <transmission name="right_steering_hinge_joint_transmission">
    <type>transmission_interface/SimpleTransmission</type>
    <joint name="right_steering_hinge_joint">
      <hardwareInterface>position</hardwareInterface>
    </joint>
    <actuator name="right_steering_hinge_joint_actuator">
      <hardwareInterface>position</hardwareInterface>
      <mechanicalReduction>1</mechanicalReduction>
    </actuator>
  </transmission>
  <transmission name="rear_left_steering_hinge_joint_transmission">
    <type>transmission_interface/SimpleTransmission</type>
    <joint name="rear_left_steering_hinge_joint">
      <hardwareInterface>position</hardwareInterface>
    </joint>
    <actuator name="rear_left_steering_hinge_joint_actuator">
      <hardwareInterface>position</hardwareInterface>
      <mechanicalReduction>1</mechanicalReduction>
    </actuator>
  </transmission>
  <transmission name="rear_right_steering_hinge_joint_transmission">
    <type>transmission_interface/SimpleTransmission</type>
    <joint name="rear_right_steering_hinge_joint">
      <hardwareInterface>position</hardwareInterface>
    </joint>
    <actuator name="rear_right_steering_hinge_joint_actuator">
      <hardwareInterface>position</hardwareInterface>
      <mechanicalReduction>1</mechanicalReduction>
    </actuator>
  </transmission>
  <gazebo reference="base_link">
    <mu1 value="0.0"/>
    <mu2 value="0.0"/>
    <material>Gazebo/Red</material>
  </gazebo>
  <gazebo reference="left_rear_wheel">
    <mu1 value="10.0"/>
    <mu2 value="10.0"/>
    <material>Gazebo/Black</material>
  </gazebo>
  <gazebo reference="right_rear_wheel">
    <mu1 value="10.0"/>
    <mu2 value="10.0"/>
    <material>Gazebo/Black</material>
  </gazebo>
  <gazebo reference="left_front_wheel">
    <mu1 value="10.0"/>
    <mu2 value="10.0"/>
    <material>Gazebo/Black</material>
  </gazebo>
  <gazebo reference="right_front_wheel">
    <mu1 value="10.0"/>
    <mu2 value="10.0"/>
    <material>Gazebo/Black</material>
  </gazebo>
  <ros2_control name="FWMaxRobot" type="system">
    <hardware>
      <plugin>gazebo_ros2_control/GazeboSystem</plugin>
    </hardware>
    <joint name="left_steering_hinge_joint">
      <command_interface name="position"/>
      <state_interface name="position"/>
      <state_interface name="effort"/>
    </joint>
    <joint name="right_steering_hinge_joint">
      <command_interface name="position"/>
      <state_interface name="position"/>
      <state_interface name="effort"/>
    </joint>
    <joint name="rear_left_steering_hinge_joint">
      <command_interface name="position"/>
      <state_interface name="position"/>
      <state_interface name="effort"/>
    </joint>
    <joint name="rear_right_steering_hinge_joint">
      <command_interface name="position"/>
      <state_interface name="position"/>
      <state_interface name="effort"/>
    </joint>
    <joint name="left_front_wheel_joint">
      <command_interface name="velocity"/>
      <state_interface name="velocity"/>
      <state_interface name="position"/>
      <state_interface name="effort"/>
    </joint>
    <joint name="right_front_wheel_joint">
      <command_interface name="velocity"/>
      <state_interface name="velocity"/>
      <state_interface name="position"/>
      <state_interface name="effort"/>
    </joint>
    <joint name="left_rear_wheel_joint">
      <command_interface name="velocity"/>
      <state_interface name="velocity"/>
      <state_interface name="position"/>
      <state_interface name="effort"/>
    </joint>
    <joint name="right_rear_wheel_joint">
      <command_interface name="velocity"/>
      <state_interface name="velocity"/>
      <state_interface name="position"/>
      <state_interface name="effort"/>
    </joint>
  </ros2_control>
  <gazebo>
    <plugin filename="libgazebo_ros2_control.so" name="gazebo_ros2_control">
      <robot_param>robot_description</robot_param>
      <robot_param_node>robot_state_publisher</robot_param_node>
      <parameters>/home/azif/projetcs/fw-max-ackerman/install/ackerman_description/share/ackerman_description/config/fw_max_controllers.yaml</parameters>
    </plugin>
  </gazebo>
</robot>
